<?xml version="1.0"?>
<robot xmlns:xacro="http://ros.org/wiki/xacro">
  <xacro:macro name="steering_macro" params="parent child steering_joint_name *origin">
    <joint name="${steering_joint_name}" type="revolute">
      <parent link="${parent}"/>
      <child link="${child}"/>
      <xacro:insert_block name="origin" />
      <axis xyz="0 0 1"/>
      <limit lower="-7.85" upper="7.85" effort="1e7" velocity="1e6"/>
    </joint>
    <link name="${child}">
      <inertial>
        <mass value="1.0"/>
        <inertia ixx="0.14583300" ixy="0.0" ixz="0.0" iyy="0.14583300" iyz="0.0" izz="0.125"/>
      </inertial>
      <visual>
        <origin xyz="0 0 0" rpy="1.302101 0 0"/>
        <geometry>
          <mesh filename="package://prius_description/meshes/steering_wheel.obj" scale="0.01 0.01 0.01"/>
        </geometry>
      </visual>
    </link>

  </xacro:macro>

</robot>
